{"trial_id": "006", "hyperparameters": {"space": [{"class_name": "Int", "config": {"name": "units", "default": null, "conditions": [], "min_value": 32, "max_value": 256, "step": 32, "sampling": "linear"}}, {"class_name": "Float", "config": {"name": "dropout_rate", "default": 0.1, "conditions": [], "min_value": 0.1, "max_value": 0.3, "step": 0.1, "sampling": "linear"}}, {"class_name": "Choice", "config": {"name": "learning_rate", "default": 0.01, "conditions": [], "values": [0.01, 0.001, 0.0001], "ordered": true}}], "values": {"units": 192, "dropout_rate": 0.1, "learning_rate": 0.01}}, "metrics": {"metrics": {}}, "score": null, "best_step": 0, "status": "FAILED", "message": "Traceback (most recent call last):\n  File \"c:\\Users\\chris\\anaconda3\\envs\\tensorflowgpu\\lib\\site-packages\\keras_tuner\\src\\engine\\base_tuner.py\", line 274, in _try_run_and_update_trial\n    self._run_and_update_trial(trial, *fit_args, **fit_kwargs)\n  File \"c:\\Users\\chris\\anaconda3\\envs\\tensorflowgpu\\lib\\site-packages\\keras_tuner\\src\\engine\\base_tuner.py\", line 239, in _run_and_update_trial\n    results = self.run_trial(trial, *fit_args, **fit_kwargs)\n  File \"c:\\Users\\chris\\anaconda3\\envs\\tensorflowgpu\\lib\\site-packages\\keras_tuner\\src\\engine\\tuner.py\", line 314, in run_trial\n    obj_value = self._build_and_fit_model(trial, *args, **copied_kwargs)\n  File \"c:\\Users\\chris\\anaconda3\\envs\\tensorflowgpu\\lib\\site-packages\\keras_tuner\\src\\engine\\tuner.py\", line 233, in _build_and_fit_model\n    results = self.hypermodel.fit(hp, model, *args, **kwargs)\n  File \"c:\\Users\\chris\\anaconda3\\envs\\tensorflowgpu\\lib\\site-packages\\keras_tuner\\src\\engine\\hypermodel.py\", line 149, in fit\n    return model.fit(*args, **kwargs)\n  File \"c:\\Users\\chris\\anaconda3\\envs\\tensorflowgpu\\lib\\site-packages\\keras\\utils\\traceback_utils.py\", line 70, in error_handler\n    raise e.with_traceback(filtered_tb) from None\n  File \"c:\\Users\\chris\\anaconda3\\envs\\tensorflowgpu\\lib\\site-packages\\tensorflow\\python\\eager\\execute.py\", line 54, in quick_execute\n    tensors = pywrap_tfe.TFE_Py_Execute(ctx._handle, device_name, op_name,\ntensorflow.python.framework.errors_impl.FailedPreconditionError: {{function_node __wrapped__MergeV2Checkpoints_device_/job:localhost/replica:0/task:0/device:CPU:0}} Failed to rename: lstm_tuning\\lstm_random_search\\trial_006\\checkpoint_temp/part-00000-of-00001.data-00000-of-00001 to: lstm_tuning\\lstm_random_search\\trial_006\\checkpoint.data-00000-of-00001 : The process cannot access the file because it is being used by another process.\r\n; Broken pipe [Op:MergeV2Checkpoints]\n"}